[2025-01-10 16:14:04,982 : INFO : main : Logger is implemented]
[2025-01-17 19:44:33,746 : INFO : common : yaml file: config\config.yaml loaded successfully]
[2025-01-17 19:44:33,747 : INFO : common : yaml file: params.yaml loaded successfully]
[2025-01-17 19:44:48,844 : INFO : common : yaml file: config\config.yaml loaded successfully]
[2025-01-17 19:44:48,851 : INFO : common : yaml file: params.yaml loaded successfully]
[2025-01-17 19:44:48,852 : INFO : common : created directory at: artifacts]
[2025-01-17 19:44:48,853 : INFO : common : created directory at: artifacts/data_ingestion]
[2025-01-17 19:44:54,175 : INFO : 869474269 : File:artifacts/data_ingestion/data.zip Downnloaded]
[2025-01-17 20:07:21,604 : INFO : main : DATA INGESTION STAGE has initiated]
[2025-01-17 20:07:21,604 : ERROR : main : DataIngestionPipeline.initiate_data_ingestion() missing 1 required positional argument: 'self']
Traceback (most recent call last):
  File "C:\Users\heman\Desktop\Text-Summarizer\main.py", line 8, in <module>
    initate_data_ingestion = DataIngestionPipeline.initiate_data_ingestion()
                             ^^^^^^^^^^^^^^^^^^^^^^^^^^^^^^^^^^^^^^^^^^^^^^^
TypeError: DataIngestionPipeline.initiate_data_ingestion() missing 1 required positional argument: 'self'
[2025-01-17 20:08:58,963 : INFO : main : DATA INGESTION STAGE has initiated]
[2025-01-17 20:08:58,963 : ERROR : main : DataIngestionPipeline.initiate_data_ingestion() missing 2 required positional arguments: 'self' and 'config_manager']
Traceback (most recent call last):
  File "C:\Users\heman\Desktop\Text-Summarizer\main.py", line 8, in <module>
    initate_data_ingestion = DataIngestionPipeline.initiate_data_ingestion()
                             ^^^^^^^^^^^^^^^^^^^^^^^^^^^^^^^^^^^^^^^^^^^^^^^
TypeError: DataIngestionPipeline.initiate_data_ingestion() missing 2 required positional arguments: 'self' and 'config_manager'
[2025-01-17 20:09:19,023 : INFO : main : DATA INGESTION STAGE has initiated]
[2025-01-17 20:09:19,024 : INFO : common : yaml file: config\config.yaml loaded successfully]
[2025-01-17 20:09:19,024 : INFO : common : yaml file: params.yaml loaded successfully]
[2025-01-17 20:09:19,026 : INFO : common : created directory at: artifacts]
[2025-01-17 20:09:19,026 : INFO : common : created directory at: artifacts/data_ingestion]
[2025-01-17 20:09:23,993 : INFO : data_ingestion1 : File:artifacts/data_ingestion/data.zip Downnloaded]
[2025-01-17 20:09:24,103 : INFO : main : DATA INGESTION STAGE has completed]
[2025-01-17 20:45:37,001 : INFO : config : PyTorch version 2.5.1 available.]
[2025-01-17 20:48:11,010 : INFO : common : yaml file: config\config.yaml loaded successfully]
[2025-01-17 20:48:11,019 : INFO : common : yaml file: params.yaml loaded successfully]
[2025-01-17 20:48:53,415 : INFO : common : yaml file: config\config.yaml loaded successfully]
[2025-01-17 20:48:53,416 : INFO : common : yaml file: params.yaml loaded successfully]
[2025-01-17 20:49:34,914 : INFO : common : yaml file: config\config.yaml loaded successfully]
[2025-01-17 20:49:34,914 : INFO : common : yaml file: params.yaml loaded successfully]
[2025-01-17 20:55:32,914 : INFO : config : PyTorch version 2.5.1 available.]
[2025-01-17 20:55:40,465 : INFO : common : yaml file: config\config.yaml loaded successfully]
[2025-01-17 20:55:40,472 : INFO : common : yaml file: params.yaml loaded successfully]
[2025-01-17 21:00:34,492 : INFO : common : yaml file: config\config.yaml loaded successfully]
[2025-01-17 21:00:34,494 : INFO : common : yaml file: params.yaml loaded successfully]
[2025-01-17 21:00:59,733 : INFO : common : yaml file: config\config.yaml loaded successfully]
[2025-01-17 21:00:59,733 : INFO : common : yaml file: params.yaml loaded successfully]
[2025-01-17 21:01:59,534 : INFO : common : yaml file: config\config.yaml loaded successfully]
[2025-01-17 21:01:59,535 : INFO : common : yaml file: params.yaml loaded successfully]
[2025-01-17 21:03:04,838 : INFO : common : yaml file: config\config.yaml loaded successfully]
[2025-01-17 21:03:04,839 : INFO : common : yaml file: params.yaml loaded successfully]
[2025-01-17 21:10:00,952 : INFO : common : yaml file: config\config.yaml loaded successfully]
[2025-01-17 21:10:00,953 : INFO : common : yaml file: params.yaml loaded successfully]
[2025-01-17 21:10:00,954 : INFO : common : created directory at: artifacts]
[2025-01-17 21:11:32,443 : INFO : common : yaml file: config\config.yaml loaded successfully]
[2025-01-17 21:11:32,443 : INFO : common : yaml file: params.yaml loaded successfully]
[2025-01-17 21:11:32,445 : INFO : common : created directory at: artifacts]
[2025-01-17 21:11:53,566 : INFO : common : yaml file: config\config.yaml loaded successfully]
[2025-01-17 21:11:53,566 : INFO : common : yaml file: params.yaml loaded successfully]
[2025-01-17 21:11:53,567 : INFO : common : created directory at: artifacts]
[2025-01-17 21:12:22,881 : INFO : common : yaml file: config\config.yaml loaded successfully]
[2025-01-17 21:12:22,882 : INFO : common : yaml file: params.yaml loaded successfully]
[2025-01-17 21:12:22,882 : INFO : common : created directory at: artifacts]
[2025-01-17 21:12:42,765 : INFO : common : yaml file: config\config.yaml loaded successfully]
[2025-01-17 21:12:42,766 : INFO : common : yaml file: params.yaml loaded successfully]
[2025-01-17 21:12:42,766 : INFO : common : created directory at: artifacts]
[2025-01-17 21:17:12,590 : INFO : common : yaml file: config\config.yaml loaded successfully]
[2025-01-17 21:17:12,590 : INFO : common : yaml file: params.yaml loaded successfully]
[2025-01-17 21:17:12,590 : INFO : common : created directory at: artifacts]
[2025-01-17 21:19:23,452 : INFO : common : yaml file: config\config.yaml loaded successfully]
[2025-01-17 21:19:23,453 : INFO : common : yaml file: params.yaml loaded successfully]
[2025-01-17 21:19:23,454 : INFO : common : created directory at: artifacts]
[2025-01-17 21:19:23,455 : INFO : common : created directory at: artifacts/data_ingestion]
[2025-01-17 21:19:28,418 : INFO : 869474269 : File:artifacts/data_ingestion/data.zip Downnloaded]
[2025-01-17 21:20:21,628 : INFO : config : PyTorch version 2.5.1 available.]
[2025-01-17 21:20:22,011 : INFO : common : yaml file: config\config.yaml loaded successfully]
[2025-01-17 21:20:22,012 : INFO : common : yaml file: params.yaml loaded successfully]
[2025-01-17 21:20:22,013 : INFO : common : created directory at: artifacts]
[2025-01-17 21:23:11,398 : INFO : common : yaml file: config\config.yaml loaded successfully]
[2025-01-17 21:23:11,398 : INFO : common : yaml file: params.yaml loaded successfully]
[2025-01-17 21:23:11,400 : INFO : common : created directory at: artifacts]
[2025-01-17 21:27:09,012 : INFO : common : yaml file: config\config.yaml loaded successfully]
[2025-01-17 21:27:09,012 : INFO : common : yaml file: params.yaml loaded successfully]
[2025-01-17 21:27:09,012 : INFO : common : created directory at: artifacts]
[2025-01-17 21:27:09,015 : INFO : common : created directory at: artifacts/data_transformation]
[2025-01-17 21:32:06,721 : INFO : common : yaml file: config\config.yaml loaded successfully]
[2025-01-17 21:32:06,723 : INFO : common : yaml file: params.yaml loaded successfully]
[2025-01-17 21:32:06,723 : INFO : common : created directory at: artifacts]
[2025-01-17 21:32:06,724 : INFO : common : created directory at: artifacts/data_transformation]
[2025-01-17 21:41:13,378 : INFO : config : PyTorch version 2.5.1 available.]
[2025-01-17 21:41:13,619 : INFO : main : DATA INGESTION STAGE has initiated]
[2025-01-17 21:41:13,619 : INFO : common : yaml file: config\config.yaml loaded successfully]
[2025-01-17 21:41:13,621 : INFO : common : yaml file: params.yaml loaded successfully]
[2025-01-17 21:41:13,621 : INFO : common : created directory at: artifacts]
[2025-01-17 21:41:13,621 : INFO : common : created directory at: artifacts/data_ingestion]
[2025-01-17 21:41:18,418 : INFO : data_ingestion1 : File:artifacts/data_ingestion/data.zip Downnloaded]
[2025-01-17 21:41:18,537 : INFO : main : DATA INGESTION STAGE has completed]
[2025-01-17 21:41:18,538 : INFO : main : <----------------------------------->]
[2025-01-17 21:41:18,538 : INFO : main : DATA TRANSFORMATION STAGE has initiated]
[2025-01-17 21:41:18,540 : INFO : common : yaml file: config\config.yaml loaded successfully]
[2025-01-17 21:41:18,540 : INFO : common : yaml file: params.yaml loaded successfully]
[2025-01-17 21:41:18,540 : INFO : common : created directory at: artifacts]
[2025-01-17 21:41:18,540 : INFO : common : created directory at: artifacts/data_transformation]
[2025-01-17 21:41:21,989 : INFO : main : DATA TRANSFORMATION STAGE has completed]
[2025-01-17 22:22:26,993 : INFO : config : PyTorch version 2.5.1 available.]
[2025-01-17 22:31:32,335 : INFO : common : yaml file: config\config.yaml loaded successfully]
[2025-01-17 22:31:32,338 : INFO : common : yaml file: params.yaml loaded successfully]
[2025-01-17 22:31:32,340 : INFO : common : created directory at: artifacts/model_trainer]
[2025-01-17 22:32:07,819 : INFO : common : yaml file: config\config.yaml loaded successfully]
[2025-01-17 22:32:07,820 : INFO : common : yaml file: params.yaml loaded successfully]
[2025-01-17 22:32:07,821 : INFO : common : created directory at: artifacts/model_trainer]
[2025-01-17 22:32:42,490 : INFO : common : yaml file: config\config.yaml loaded successfully]
[2025-01-17 22:32:42,491 : INFO : common : yaml file: params.yaml loaded successfully]
[2025-01-17 22:32:42,493 : INFO : common : created directory at: artifacts/model_trainer]
[2025-01-17 22:36:49,649 : INFO : common : yaml file: config\config.yaml loaded successfully]
[2025-01-17 22:36:49,653 : INFO : common : yaml file: params.yaml loaded successfully]
[2025-01-17 22:36:49,654 : INFO : common : created directory at: artifacts/model_trainer]
[2025-01-18 18:10:31,469 : INFO : config : PyTorch version 2.5.1 available.]
[2025-01-18 18:10:48,336 : INFO : common : yaml file: config\config.yaml loaded successfully]
[2025-01-18 18:10:48,343 : INFO : common : yaml file: params.yaml loaded successfully]
[2025-01-18 18:10:48,344 : INFO : common : created directory at: artifacts/model_trainer]
[2025-01-18 18:12:25,194 : INFO : common : yaml file: config\config.yaml loaded successfully]
[2025-01-18 18:12:25,195 : INFO : common : yaml file: params.yaml loaded successfully]
[2025-01-18 18:12:25,196 : INFO : common : created directory at: artifacts/model_trainer]
[2025-01-18 18:13:01,315 : INFO : common : yaml file: config\config.yaml loaded successfully]
[2025-01-18 18:13:01,315 : INFO : common : yaml file: params.yaml loaded successfully]
[2025-01-18 18:13:01,317 : INFO : common : created directory at: artifacts/model_trainer]
[2025-01-18 18:23:07,644 : INFO : config : PyTorch version 2.5.1 available.]
[2025-01-18 18:23:08,081 : INFO : main : DATA INGESTION STAGE has initiated]
[2025-01-18 18:23:08,093 : INFO : common : yaml file: config\config.yaml loaded successfully]
[2025-01-18 18:23:08,093 : INFO : common : yaml file: params.yaml loaded successfully]
[2025-01-18 18:23:08,095 : INFO : common : created directory at: artifacts]
[2025-01-18 18:23:08,095 : INFO : common : created directory at: artifacts/data_ingestion]
[2025-01-18 18:23:08,095 : INFO : data_ingestion1 : file already exists]
[2025-01-18 18:23:08,204 : INFO : main : DATA INGESTION STAGE has completed]
[2025-01-18 18:23:08,204 : INFO : main : <----------------------------------->]
[2025-01-18 18:23:08,206 : INFO : main : DATA TRANSFORMATION STAGE has initiated]
[2025-01-18 18:23:08,207 : INFO : common : yaml file: config\config.yaml loaded successfully]
[2025-01-18 18:23:08,207 : INFO : common : yaml file: params.yaml loaded successfully]
[2025-01-18 18:23:08,207 : INFO : common : created directory at: artifacts]
[2025-01-18 18:23:08,207 : INFO : common : created directory at: artifacts/data_transformation]
[2025-01-18 18:23:11,559 : ERROR : main : [Errno 22] Invalid argument: 'C:/Users/heman/Desktop/Text-Summarizer/artifacts/data_transformation/samsum_dataset_factored/train/data-00000-of-00001.arrow']
Traceback (most recent call last):
  File "C:\Users\heman\Desktop\Text-Summarizer\main.py", line 16, in <module>
    initiate_data_transformation=DataTransformationPipeline.initiate_data_transformation()
                                 ^^^^^^^^^^^^^^^^^^^^^^^^^^^^^^^^^^^^^^^^^^^^^^^^^^^^^^^^^
  File "C:\Users\heman\Desktop\Text-Summarizer\src\Text_Summarizer\pipeline\stage_data_transfromation.py", line 14, in initiate_data_transformation
    data_transformation.convert()
  File "C:\Users\heman\Desktop\Text-Summarizer\src\Text_Summarizer\components\data_transformation1.py", line 27, in convert
    dataset_samsum_pt.save_to_disk(os.path.join(self.config.root_dir , 'samsum_dataset_factored'))
  File "C:\Users\heman\Desktop\Text-Summarizer\myvenv\Lib\site-packages\datasets\dataset_dict.py", line 1284, in save_to_disk
    dataset.save_to_disk(
  File "C:\Users\heman\Desktop\Text-Summarizer\myvenv\Lib\site-packages\datasets\arrow_dataset.py", line 1560, in save_to_disk
    for job_id, done, content in Dataset._save_to_disk_single(**kwargs):
  File "C:\Users\heman\Desktop\Text-Summarizer\myvenv\Lib\site-packages\datasets\arrow_dataset.py", line 1584, in _save_to_disk_single
    writer = ArrowWriter(
             ^^^^^^^^^^^^
  File "C:\Users\heman\Desktop\Text-Summarizer\myvenv\Lib\site-packages\datasets\arrow_writer.py", line 373, in __init__
    self.stream = self._fs.open(path, "wb")
                  ^^^^^^^^^^^^^^^^^^^^^^^^^
  File "C:\Users\heman\Desktop\Text-Summarizer\myvenv\Lib\site-packages\fsspec\spec.py", line 1303, in open
    f = self._open(
        ^^^^^^^^^^^
  File "C:\Users\heman\Desktop\Text-Summarizer\myvenv\Lib\site-packages\fsspec\implementations\local.py", line 195, in _open
    return LocalFileOpener(path, mode, fs=self, **kwargs)
           ^^^^^^^^^^^^^^^^^^^^^^^^^^^^^^^^^^^^^^^^^^^^^^
  File "C:\Users\heman\Desktop\Text-Summarizer\myvenv\Lib\site-packages\fsspec\implementations\local.py", line 359, in __init__
    self._open()
  File "C:\Users\heman\Desktop\Text-Summarizer\myvenv\Lib\site-packages\fsspec\implementations\local.py", line 364, in _open
    self.f = open(self.path, mode=self.mode)
             ^^^^^^^^^^^^^^^^^^^^^^^^^^^^^^^
OSError: [Errno 22] Invalid argument: 'C:/Users/heman/Desktop/Text-Summarizer/artifacts/data_transformation/samsum_dataset_factored/train/data-00000-of-00001.arrow'
[2025-01-18 18:23:37,511 : INFO : config : PyTorch version 2.5.1 available.]
[2025-01-18 18:23:37,840 : INFO : main : DATA INGESTION STAGE has initiated]
[2025-01-18 18:23:37,846 : INFO : common : yaml file: config\config.yaml loaded successfully]
[2025-01-18 18:23:37,846 : INFO : common : yaml file: params.yaml loaded successfully]
[2025-01-18 18:23:37,846 : INFO : common : created directory at: artifacts]
[2025-01-18 18:23:37,848 : INFO : common : created directory at: artifacts/data_ingestion]
[2025-01-18 18:23:44,635 : INFO : data_ingestion1 : File:artifacts/data_ingestion/data.zip Downnloaded]
[2025-01-18 18:23:44,736 : INFO : main : DATA INGESTION STAGE has completed]
[2025-01-18 18:23:44,736 : INFO : main : <----------------------------------->]
[2025-01-18 18:23:44,736 : INFO : main : DATA TRANSFORMATION STAGE has initiated]
[2025-01-18 18:23:44,737 : INFO : common : yaml file: config\config.yaml loaded successfully]
[2025-01-18 18:23:44,737 : INFO : common : yaml file: params.yaml loaded successfully]
[2025-01-18 18:23:44,737 : INFO : common : created directory at: artifacts]
[2025-01-18 18:23:44,739 : INFO : common : created directory at: artifacts/data_transformation]
[2025-01-18 18:23:48,075 : INFO : main : DATA TRANSFORMATION STAGE has completed]
[2025-01-18 18:23:48,075 : INFO : main : <----------------------------------->]
[2025-01-18 18:23:48,075 : INFO : main : MODEL STAGE has initiated]
[2025-01-18 18:23:48,076 : ERROR : main : ModelTrainerPipeline.train() missing 1 required positional argument: 'self']
Traceback (most recent call last):
  File "C:\Users\heman\Desktop\Text-Summarizer\main.py", line 20, in <module>
    initiate_model_training=ModelTrainerPipeline.train()
                            ^^^^^^^^^^^^^^^^^^^^^^^^^^^^
TypeError: ModelTrainerPipeline.train() missing 1 required positional argument: 'self'
[2025-01-18 18:26:03,214 : INFO : config : PyTorch version 2.5.1 available.]
[2025-01-18 18:26:03,541 : INFO : main : DATA INGESTION STAGE has initiated]
[2025-01-18 18:26:03,541 : INFO : common : yaml file: config\config.yaml loaded successfully]
[2025-01-18 18:26:03,541 : INFO : common : yaml file: params.yaml loaded successfully]
[2025-01-18 18:26:03,554 : INFO : common : created directory at: artifacts]
[2025-01-18 18:26:03,554 : INFO : common : created directory at: artifacts/data_ingestion]
[2025-01-18 18:26:03,554 : INFO : data_ingestion1 : file already exists]
[2025-01-18 18:26:03,623 : INFO : main : DATA INGESTION STAGE has completed]
[2025-01-18 18:26:03,623 : INFO : main : <----------------------------------->]
[2025-01-18 18:26:03,623 : INFO : main : DATA TRANSFORMATION STAGE has initiated]
[2025-01-18 18:26:03,637 : INFO : common : yaml file: config\config.yaml loaded successfully]
[2025-01-18 18:26:03,637 : INFO : common : yaml file: params.yaml loaded successfully]
[2025-01-18 18:26:03,637 : INFO : common : created directory at: artifacts]
[2025-01-18 18:26:03,637 : INFO : common : created directory at: artifacts/data_transformation]
[2025-01-18 18:26:04,971 : INFO : main : DATA TRANSFORMATION STAGE has completed]
[2025-01-18 18:26:04,971 : INFO : main : <----------------------------------->]
[2025-01-18 18:26:04,971 : INFO : main : MODEL STAGE has initiated]
[2025-01-18 18:26:04,976 : ERROR : main : ModelTrainerPipeline.train() missing 1 required positional argument: 'self']
Traceback (most recent call last):
  File "C:\Users\heman\Desktop\Text-Summarizer\main.py", line 20, in <module>
    initiate_model_training=ModelTrainerPipeline.train()
                            ^^^^^^^^^^^^^^^^^^^^^^^^^^^^
TypeError: ModelTrainerPipeline.train() missing 1 required positional argument: 'self'
[2025-01-18 18:27:14,661 : INFO : config : PyTorch version 2.5.1 available.]
[2025-01-18 18:27:15,009 : INFO : main : DATA INGESTION STAGE has initiated]
[2025-01-18 18:27:15,016 : INFO : common : yaml file: config\config.yaml loaded successfully]
[2025-01-18 18:27:15,016 : INFO : common : yaml file: params.yaml loaded successfully]
[2025-01-18 18:27:15,016 : INFO : common : created directory at: artifacts]
[2025-01-18 18:27:15,016 : INFO : common : created directory at: artifacts/data_ingestion]
[2025-01-18 18:27:15,016 : INFO : data_ingestion1 : file already exists]
[2025-01-18 18:27:15,096 : INFO : main : DATA INGESTION STAGE has completed]
[2025-01-18 18:27:15,096 : INFO : main : <----------------------------------->]
[2025-01-18 18:27:15,096 : INFO : main : DATA TRANSFORMATION STAGE has initiated]
[2025-01-18 18:27:15,102 : INFO : common : yaml file: config\config.yaml loaded successfully]
[2025-01-18 18:27:15,102 : INFO : common : yaml file: params.yaml loaded successfully]
[2025-01-18 18:27:15,102 : INFO : common : created directory at: artifacts]
[2025-01-18 18:27:15,102 : INFO : common : created directory at: artifacts/data_transformation]
[2025-01-18 18:27:16,494 : INFO : main : DATA TRANSFORMATION STAGE has completed]
[2025-01-18 18:27:16,494 : INFO : main : <----------------------------------->]
[2025-01-18 18:27:16,494 : INFO : main : MODEL STAGE has initiated]
[2025-01-18 18:27:16,494 : ERROR : main : ModelTrainerPipeline.train() missing 1 required positional argument: 'self']
Traceback (most recent call last):
  File "C:\Users\heman\Desktop\Text-Summarizer\main.py", line 20, in <module>
    initiate_model_training=ModelTrainerPipeline.train()
                            ^^^^^^^^^^^^^^^^^^^^^^^^^^^^
TypeError: ModelTrainerPipeline.train() missing 1 required positional argument: 'self'
[2025-01-18 18:42:31,802 : INFO : config : PyTorch version 2.5.1 available.]
[2025-01-18 18:42:32,141 : INFO : main : DATA INGESTION STAGE has initiated]
[2025-01-18 18:42:32,145 : INFO : common : yaml file: config\config.yaml loaded successfully]
[2025-01-18 18:42:32,145 : INFO : common : yaml file: params.yaml loaded successfully]
[2025-01-18 18:42:32,145 : INFO : common : created directory at: artifacts]
[2025-01-18 18:42:32,145 : INFO : common : created directory at: artifacts/data_ingestion]
[2025-01-18 18:42:32,145 : INFO : data_ingestion1 : file already exists]
[2025-01-18 18:42:32,232 : INFO : main : DATA INGESTION STAGE has completed]
[2025-01-18 18:42:32,232 : INFO : main : <----------------------------------->]
[2025-01-18 18:42:32,232 : INFO : main : DATA TRANSFORMATION STAGE has initiated]
[2025-01-18 18:42:32,237 : INFO : common : yaml file: config\config.yaml loaded successfully]
[2025-01-18 18:42:32,237 : INFO : common : yaml file: params.yaml loaded successfully]
[2025-01-18 18:42:32,237 : INFO : common : created directory at: artifacts]
[2025-01-18 18:42:32,238 : INFO : common : created directory at: artifacts/data_transformation]
[2025-01-18 18:42:33,818 : INFO : main : DATA TRANSFORMATION STAGE has completed]
[2025-01-18 18:42:33,818 : INFO : main : <----------------------------------->]
[2025-01-18 18:42:33,818 : INFO : main : MODEL STAGE has initiated]
[2025-01-18 18:42:33,818 : ERROR : main : type object 'ModelTrainerPipeline' has no attribute 'train']
Traceback (most recent call last):
  File "C:\Users\heman\Desktop\Text-Summarizer\main.py", line 20, in <module>
    initiate_model_training=ModelTrainerPipeline.train()
                            ^^^^^^^^^^^^^^^^^^^^^^^^^^
AttributeError: type object 'ModelTrainerPipeline' has no attribute 'train'
[2025-01-18 18:43:45,482 : INFO : config : PyTorch version 2.5.1 available.]
[2025-01-18 18:43:45,779 : INFO : main : DATA INGESTION STAGE has initiated]
[2025-01-18 18:43:45,779 : INFO : common : yaml file: config\config.yaml loaded successfully]
[2025-01-18 18:43:45,779 : INFO : common : yaml file: params.yaml loaded successfully]
[2025-01-18 18:43:45,779 : INFO : common : created directory at: artifacts]
[2025-01-18 18:43:45,779 : INFO : common : created directory at: artifacts/data_ingestion]
[2025-01-18 18:43:45,779 : INFO : data_ingestion1 : file already exists]
[2025-01-18 18:43:45,866 : INFO : main : DATA INGESTION STAGE has completed]
[2025-01-18 18:43:45,866 : INFO : main : <----------------------------------->]
[2025-01-18 18:43:45,866 : INFO : main : DATA TRANSFORMATION STAGE has initiated]
[2025-01-18 18:43:45,866 : INFO : common : yaml file: config\config.yaml loaded successfully]
[2025-01-18 18:43:45,866 : INFO : common : yaml file: params.yaml loaded successfully]
[2025-01-18 18:43:45,866 : INFO : common : created directory at: artifacts]
[2025-01-18 18:43:45,866 : INFO : common : created directory at: artifacts/data_transformation]
[2025-01-18 18:43:47,345 : INFO : main : DATA TRANSFORMATION STAGE has completed]
[2025-01-18 18:43:47,345 : INFO : main : <----------------------------------->]
[2025-01-18 18:43:47,345 : INFO : main : MODEL STAGE has initiated]
[2025-01-18 18:43:47,345 : ERROR : main : type object 'ModelTrainerPipeline' has no attribute 'train']
Traceback (most recent call last):
  File "C:\Users\heman\Desktop\Text-Summarizer\main.py", line 20, in <module>
    initiate_model_training=ModelTrainerPipeline.train()
                            ^^^^^^^^^^^^^^^^^^^^^^^^^^
AttributeError: type object 'ModelTrainerPipeline' has no attribute 'train'
[2025-01-18 18:46:17,105 : INFO : config : PyTorch version 2.5.1 available.]
[2025-01-18 18:46:17,399 : INFO : main : DATA INGESTION STAGE has initiated]
[2025-01-18 18:46:17,407 : INFO : common : yaml file: config\config.yaml loaded successfully]
[2025-01-18 18:46:17,408 : INFO : common : yaml file: params.yaml loaded successfully]
[2025-01-18 18:46:17,408 : INFO : common : created directory at: artifacts]
[2025-01-18 18:46:17,409 : INFO : common : created directory at: artifacts/data_ingestion]
[2025-01-18 18:46:17,409 : INFO : data_ingestion1 : file already exists]
[2025-01-18 18:46:17,484 : INFO : main : DATA INGESTION STAGE has completed]
[2025-01-18 18:46:17,484 : INFO : main : <----------------------------------->]
[2025-01-18 18:46:17,484 : INFO : main : DATA TRANSFORMATION STAGE has initiated]
[2025-01-18 18:46:17,484 : INFO : common : yaml file: config\config.yaml loaded successfully]
[2025-01-18 18:46:17,484 : INFO : common : yaml file: params.yaml loaded successfully]
[2025-01-18 18:46:17,484 : INFO : common : created directory at: artifacts]
[2025-01-18 18:46:17,484 : INFO : common : created directory at: artifacts/data_transformation]
[2025-01-18 18:46:19,004 : INFO : main : DATA TRANSFORMATION STAGE has completed]
[2025-01-18 18:46:19,004 : INFO : main : <----------------------------------->]
[2025-01-18 18:46:19,004 : INFO : main : MODEL STAGE has initiated]
[2025-01-18 18:46:19,005 : ERROR : main : ModelTrainerPipeline.initiate_train() missing 1 required positional argument: 'self']
Traceback (most recent call last):
  File "C:\Users\heman\Desktop\Text-Summarizer\main.py", line 20, in <module>
    initiate_model_training=ModelTrainerPipeline.initiate_train()
                            ^^^^^^^^^^^^^^^^^^^^^^^^^^^^^^^^^^^^^
TypeError: ModelTrainerPipeline.initiate_train() missing 1 required positional argument: 'self'
[2025-01-18 18:47:08,016 : INFO : config : PyTorch version 2.5.1 available.]
[2025-01-18 18:47:08,312 : INFO : main : DATA INGESTION STAGE has initiated]
[2025-01-18 18:47:08,312 : INFO : common : yaml file: config\config.yaml loaded successfully]
[2025-01-18 18:47:08,326 : INFO : common : yaml file: params.yaml loaded successfully]
[2025-01-18 18:47:08,326 : INFO : common : created directory at: artifacts]
[2025-01-18 18:47:08,328 : INFO : common : created directory at: artifacts/data_ingestion]
[2025-01-18 18:47:08,328 : INFO : data_ingestion1 : file already exists]
[2025-01-18 18:47:08,408 : INFO : main : DATA INGESTION STAGE has completed]
[2025-01-18 18:47:08,408 : INFO : main : <----------------------------------->]
[2025-01-18 18:47:08,409 : INFO : main : DATA TRANSFORMATION STAGE has initiated]
[2025-01-18 18:47:08,410 : INFO : common : yaml file: config\config.yaml loaded successfully]
[2025-01-18 18:47:08,410 : INFO : common : yaml file: params.yaml loaded successfully]
[2025-01-18 18:47:08,410 : INFO : common : created directory at: artifacts]
[2025-01-18 18:47:08,410 : INFO : common : created directory at: artifacts/data_transformation]
[2025-01-18 18:47:09,898 : INFO : main : DATA TRANSFORMATION STAGE has completed]
[2025-01-18 18:47:09,898 : INFO : main : <----------------------------------->]
[2025-01-18 18:47:09,898 : INFO : main : MODEL STAGE has initiated]
[2025-01-18 18:47:09,899 : INFO : common : yaml file: config\config.yaml loaded successfully]
[2025-01-18 18:47:09,900 : INFO : common : yaml file: params.yaml loaded successfully]
[2025-01-18 18:47:09,900 : ERROR : main : "'ConfigBox' object has no attribute 'root_dir'"]
Traceback (most recent call last):
  File "C:\Users\heman\Desktop\Text-Summarizer\myvenv\Lib\site-packages\box\box.py", line 503, in __getitem__
    return super().__getitem__(item)
           ^^^^^^^^^^^^^^^^^^^^^^^^^
KeyError: 'root_dir'

The above exception was the direct cause of the following exception:

Traceback (most recent call last):
  File "C:\Users\heman\Desktop\Text-Summarizer\myvenv\Lib\site-packages\box\box.py", line 536, in __getattr__
    value = self.__getitem__(item, _ignore_default=True)
            ^^^^^^^^^^^^^^^^^^^^^^^^^^^^^^^^^^^^^^^^^^^^
  File "C:\Users\heman\Desktop\Text-Summarizer\myvenv\Lib\site-packages\box\box.py", line 524, in __getitem__
    raise BoxKeyError(str(err)) from _exception_cause(err)
box.exceptions.BoxKeyError: "'root_dir'"

During handling of the above exception, another exception occurred:

Traceback (most recent call last):
  File "C:\Users\heman\Desktop\Text-Summarizer\myvenv\Lib\site-packages\box\box.py", line 538, in __getattr__
    value = object.__getattribute__(self, item)
            ^^^^^^^^^^^^^^^^^^^^^^^^^^^^^^^^^^^
AttributeError: 'ConfigBox' object has no attribute 'root_dir'

The above exception was the direct cause of the following exception:

Traceback (most recent call last):
  File "C:\Users\heman\Desktop\Text-Summarizer\myvenv\Lib\site-packages\box\config_box.py", line 28, in __getattr__
    return super().__getattr__(item)
           ^^^^^^^^^^^^^^^^^^^^^^^^^
  File "C:\Users\heman\Desktop\Text-Summarizer\myvenv\Lib\site-packages\box\box.py", line 552, in __getattr__
    raise BoxKeyError(str(err)) from _exception_cause(err)
box.exceptions.BoxKeyError: "'ConfigBox' object has no attribute 'root_dir'"

During handling of the above exception, another exception occurred:

Traceback (most recent call last):
  File "C:\Users\heman\Desktop\Text-Summarizer\myvenv\Lib\site-packages\box\box.py", line 503, in __getitem__
    return super().__getitem__(item)
           ^^^^^^^^^^^^^^^^^^^^^^^^^
KeyError: 'root_dir'

The above exception was the direct cause of the following exception:

Traceback (most recent call last):
  File "C:\Users\heman\Desktop\Text-Summarizer\myvenv\Lib\site-packages\box\box.py", line 536, in __getattr__
    value = self.__getitem__(item, _ignore_default=True)
            ^^^^^^^^^^^^^^^^^^^^^^^^^^^^^^^^^^^^^^^^^^^^
  File "C:\Users\heman\Desktop\Text-Summarizer\myvenv\Lib\site-packages\box\box.py", line 524, in __getitem__
    raise BoxKeyError(str(err)) from _exception_cause(err)
box.exceptions.BoxKeyError: "'root_dir'"

During handling of the above exception, another exception occurred:

Traceback (most recent call last):
  File "C:\Users\heman\Desktop\Text-Summarizer\myvenv\Lib\site-packages\box\box.py", line 538, in __getattr__
    value = object.__getattribute__(self, item)
            ^^^^^^^^^^^^^^^^^^^^^^^^^^^^^^^^^^^
AttributeError: 'ConfigBox' object has no attribute 'root_dir'

The above exception was the direct cause of the following exception:

Traceback (most recent call last):
  File "C:\Users\heman\Desktop\Text-Summarizer\main.py", line 20, in <module>
    initiate_model_training=ModelTrainerPipeline.initiate_train()
                            ^^^^^^^^^^^^^^^^^^^^^^^^^^^^^^^^^^^^^
  File "C:\Users\heman\Desktop\Text-Summarizer\src\Text_Summarizer\pipeline\stage_model_training.py", line 9, in initiate_train
    config = ConfigurationManagerMT()
             ^^^^^^^^^^^^^^^^^^^^^^^^
  File "C:\Users\heman\Desktop\Text-Summarizer\src\Text_Summarizer\config\configuration.py", line 53, in __init__
    create_directories([self.config.root_dir])
                        ^^^^^^^^^^^^^^^^^^^^
  File "C:\Users\heman\Desktop\Text-Summarizer\myvenv\Lib\site-packages\box\config_box.py", line 30, in __getattr__
    return super().__getattr__(item.lower())
           ^^^^^^^^^^^^^^^^^^^^^^^^^^^^^^^^^
  File "C:\Users\heman\Desktop\Text-Summarizer\myvenv\Lib\site-packages\box\box.py", line 552, in __getattr__
    raise BoxKeyError(str(err)) from _exception_cause(err)
box.exceptions.BoxKeyError: "'ConfigBox' object has no attribute 'root_dir'"
[2025-01-18 18:48:12,278 : INFO : config : PyTorch version 2.5.1 available.]
[2025-01-18 18:48:12,586 : INFO : main : DATA INGESTION STAGE has initiated]
[2025-01-18 18:48:12,587 : INFO : common : yaml file: config\config.yaml loaded successfully]
[2025-01-18 18:48:12,587 : INFO : common : yaml file: params.yaml loaded successfully]
[2025-01-18 18:48:12,587 : INFO : common : created directory at: artifacts]
[2025-01-18 18:48:12,587 : INFO : common : created directory at: artifacts/data_ingestion]
[2025-01-18 18:48:12,587 : INFO : data_ingestion1 : file already exists]
[2025-01-18 18:48:12,671 : INFO : main : DATA INGESTION STAGE has completed]
[2025-01-18 18:48:12,671 : INFO : main : <----------------------------------->]
[2025-01-18 18:48:12,671 : INFO : main : DATA TRANSFORMATION STAGE has initiated]
[2025-01-18 18:48:12,672 : INFO : common : yaml file: config\config.yaml loaded successfully]
[2025-01-18 18:48:12,672 : INFO : common : yaml file: params.yaml loaded successfully]
[2025-01-18 18:48:12,673 : INFO : common : created directory at: artifacts]
[2025-01-18 18:48:12,673 : INFO : common : created directory at: artifacts/data_transformation]
[2025-01-18 18:48:13,792 : INFO : main : DATA TRANSFORMATION STAGE has completed]
[2025-01-18 18:48:13,792 : INFO : main : <----------------------------------->]
[2025-01-18 18:48:13,793 : INFO : main : MODEL STAGE has initiated]
[2025-01-18 18:48:13,793 : INFO : common : yaml file: config\config.yaml loaded successfully]
[2025-01-18 18:48:13,793 : INFO : common : yaml file: params.yaml loaded successfully]
[2025-01-18 18:48:13,802 : INFO : common : created directory at: artifacts/model_trainer]
[2025-01-18 19:11:08,714 : INFO : config : PyTorch version 2.5.1 available.]
[2025-01-18 19:35:32,925 : INFO : common : yaml file: config\config.yaml loaded successfully]
[2025-01-18 19:35:32,926 : INFO : common : yaml file: params.yaml loaded successfully]
[2025-01-18 19:35:58,688 : INFO : common : yaml file: config\config.yaml loaded successfully]
[2025-01-18 19:35:58,689 : INFO : common : yaml file: params.yaml loaded successfully]
[2025-01-18 19:36:58,563 : INFO : common : yaml file: config\config.yaml loaded successfully]
[2025-01-18 19:36:58,565 : INFO : common : yaml file: params.yaml loaded successfully]
[2025-01-18 19:37:24,819 : INFO : common : yaml file: config\config.yaml loaded successfully]
[2025-01-18 19:37:24,819 : INFO : common : yaml file: params.yaml loaded successfully]
[2025-01-18 19:37:52,576 : INFO : common : yaml file: config\config.yaml loaded successfully]
[2025-01-18 19:37:52,576 : INFO : common : yaml file: params.yaml loaded successfully]
[2025-01-18 19:38:21,743 : INFO : common : yaml file: config\config.yaml loaded successfully]
[2025-01-18 19:38:21,743 : INFO : common : yaml file: params.yaml loaded successfully]
[2025-01-18 19:41:01,351 : INFO : common : yaml file: config\config.yaml loaded successfully]
[2025-01-18 19:41:01,352 : INFO : common : yaml file: params.yaml loaded successfully]
[2025-01-18 19:41:01,352 : INFO : common : created directory at: artifacts]
[2025-01-18 19:42:06,163 : INFO : common : yaml file: config\config.yaml loaded successfully]
[2025-01-18 19:42:06,164 : INFO : common : yaml file: params.yaml loaded successfully]
[2025-01-18 19:42:06,165 : INFO : common : created directory at: artifacts]
[2025-01-18 19:42:06,166 : INFO : common : created directory at: artifacts/model_evaluation]
[2025-01-18 22:07:58,744 : INFO : rouge_scorer : Using default tokenizer.]
[2025-01-19 12:28:37,191 : INFO : config : PyTorch version 2.5.1 available.]
[2025-01-19 12:28:38,550 : INFO : main : DATA INGESTION STAGE has initiated]
[2025-01-19 12:28:38,563 : INFO : common : yaml file: config\config.yaml loaded successfully]
[2025-01-19 12:28:38,573 : INFO : common : yaml file: params.yaml loaded successfully]
[2025-01-19 12:28:38,573 : INFO : common : created directory at: artifacts]
[2025-01-19 12:28:38,573 : INFO : common : created directory at: artifacts/data_ingestion]
[2025-01-19 12:28:44,312 : INFO : data_ingestion1 : File:artifacts/data_ingestion/data.zip Downnloaded]
[2025-01-19 12:28:44,488 : INFO : main : DATA INGESTION STAGE has completed]
[2025-01-19 12:28:44,488 : INFO : main : <----------------------------------->]
[2025-01-19 12:28:44,488 : INFO : main : DATA TRANSFORMATION STAGE has initiated]
[2025-01-19 12:28:44,488 : INFO : common : yaml file: config\config.yaml loaded successfully]
[2025-01-19 12:28:44,492 : INFO : common : yaml file: params.yaml loaded successfully]
[2025-01-19 12:28:44,492 : INFO : common : created directory at: artifacts]
[2025-01-19 12:28:44,492 : INFO : common : created directory at: artifacts/data_transformation]
[2025-01-19 12:28:50,378 : INFO : main : DATA TRANSFORMATION STAGE has completed]
[2025-01-19 12:28:50,378 : INFO : main : <----------------------------------->]
[2025-01-19 12:28:50,378 : INFO : main : <----------------------------------->]
[2025-01-19 12:28:50,378 : INFO : main : MODEL TRAINING STAGE has initiated]
[2025-01-19 12:28:50,381 : INFO : common : yaml file: config\config.yaml loaded successfully]
[2025-01-19 12:28:50,381 : INFO : common : yaml file: params.yaml loaded successfully]
[2025-01-19 12:28:50,381 : INFO : common : created directory at: artifacts]
[2025-01-19 12:28:50,385 : INFO : common : created directory at: artifacts/model_evaluation]
[2025-01-19 12:28:50,385 : ERROR : main : name 'AutoModelForSeq2SeqLM' is not defined]
Traceback (most recent call last):
  File "C:\Users\heman\Desktop\Text-Summarizer\main.py", line 26, in <module>
    initiate_model_evaluation=ModelEvaluationPipeline.evaluate_model()
                              ^^^^^^^^^^^^^^^^^^^^^^^^^^^^^^^^^^^^^^^^
  File "C:\Users\heman\Desktop\Text-Summarizer\src\Text_Summarizer\pipeline\stage_model_evaluation.py", line 13, in evaluate_model
    model_eval.evaluate()
  File "C:\Users\heman\Desktop\Text-Summarizer\src\Text_Summarizer\components\model_evaluation.py", line 60, in evaluate
    model = AutoModelForSeq2SeqLM.from_pretrained(self.config.model_path)
            ^^^^^^^^^^^^^^^^^^^^^
NameError: name 'AutoModelForSeq2SeqLM' is not defined
[2025-01-19 12:30:18,840 : INFO : config : PyTorch version 2.5.1 available.]
[2025-01-19 12:30:19,240 : INFO : main : DATA INGESTION STAGE has initiated]
[2025-01-19 12:30:19,240 : INFO : common : yaml file: config\config.yaml loaded successfully]
[2025-01-19 12:30:19,243 : INFO : common : yaml file: params.yaml loaded successfully]
[2025-01-19 12:30:19,244 : INFO : common : created directory at: artifacts]
[2025-01-19 12:30:19,244 : INFO : common : created directory at: artifacts/data_ingestion]
[2025-01-19 12:30:19,244 : INFO : data_ingestion1 : file already exists]
[2025-01-19 12:30:19,335 : INFO : main : DATA INGESTION STAGE has completed]
[2025-01-19 12:30:19,335 : INFO : main : <----------------------------------->]
[2025-01-19 12:30:19,335 : INFO : main : DATA TRANSFORMATION STAGE has initiated]
[2025-01-19 12:30:19,337 : INFO : common : yaml file: config\config.yaml loaded successfully]
[2025-01-19 12:30:19,337 : INFO : common : yaml file: params.yaml loaded successfully]
[2025-01-19 12:30:19,337 : INFO : common : created directory at: artifacts]
[2025-01-19 12:30:19,337 : INFO : common : created directory at: artifacts/data_transformation]
[2025-01-19 12:30:21,941 : INFO : main : DATA TRANSFORMATION STAGE has completed]
[2025-01-19 12:30:21,941 : INFO : main : <----------------------------------->]
[2025-01-19 12:30:21,941 : INFO : main : <----------------------------------->]
[2025-01-19 12:30:21,941 : INFO : main : MODEL TRAINING STAGE has initiated]
[2025-01-19 12:30:21,948 : INFO : common : yaml file: config\config.yaml loaded successfully]
[2025-01-19 12:30:21,949 : INFO : common : yaml file: params.yaml loaded successfully]
[2025-01-19 12:30:21,949 : INFO : common : created directory at: artifacts]
[2025-01-19 12:30:21,949 : INFO : common : created directory at: artifacts/model_evaluation]
[2025-01-19 12:30:21,949 : ERROR : main : Incorrect path_or_model_id: 'artifacts/model_trainer/pegasus-samsum-trained'. Please provide either the path to a local folder or the repo_id of a model on the Hub.]
Traceback (most recent call last):
  File "C:\Users\heman\Desktop\Text-Summarizer\myvenv\Lib\site-packages\transformers\utils\hub.py", line 403, in cached_file
    resolved_file = hf_hub_download(
                    ^^^^^^^^^^^^^^^^
  File "C:\Users\heman\Desktop\Text-Summarizer\myvenv\Lib\site-packages\huggingface_hub\utils\_validators.py", line 106, in _inner_fn
    validate_repo_id(arg_value)
  File "C:\Users\heman\Desktop\Text-Summarizer\myvenv\Lib\site-packages\huggingface_hub\utils\_validators.py", line 154, in validate_repo_id
    raise HFValidationError(
huggingface_hub.errors.HFValidationError: Repo id must be in the form 'repo_name' or 'namespace/repo_name': 'artifacts/model_trainer/pegasus-samsum-trained'. Use `repo_type` argument if needed.

The above exception was the direct cause of the following exception:

Traceback (most recent call last):
  File "C:\Users\heman\Desktop\Text-Summarizer\main.py", line 26, in <module>
    initiate_model_evaluation=ModelEvaluationPipeline.evaluate_model()
                              ^^^^^^^^^^^^^^^^^^^^^^^^^^^^^^^^^^^^^^^^
  File "C:\Users\heman\Desktop\Text-Summarizer\src\Text_Summarizer\pipeline\stage_model_evaluation.py", line 13, in evaluate_model
    model_eval.evaluate()
  File "C:\Users\heman\Desktop\Text-Summarizer\src\Text_Summarizer\components\model_evaluation.py", line 61, in evaluate
    model = AutoModelForSeq2SeqLM.from_pretrained(self.config.model_path)
            ^^^^^^^^^^^^^^^^^^^^^^^^^^^^^^^^^^^^^^^^^^^^^^^^^^^^^^^^^^^^^
  File "C:\Users\heman\Desktop\Text-Summarizer\myvenv\Lib\site-packages\transformers\models\auto\auto_factory.py", line 487, in from_pretrained
    resolved_config_file = cached_file(
                           ^^^^^^^^^^^^
  File "C:\Users\heman\Desktop\Text-Summarizer\myvenv\Lib\site-packages\transformers\utils\hub.py", line 469, in cached_file
    raise EnvironmentError(
OSError: Incorrect path_or_model_id: 'artifacts/model_trainer/pegasus-samsum-trained'. Please provide either the path to a local folder or the repo_id of a model on the Hub.
[2025-01-19 12:32:28,428 : INFO : config : PyTorch version 2.5.1 available.]
[2025-01-19 12:32:28,811 : INFO : main : DATA INGESTION STAGE has initiated]
[2025-01-19 12:32:28,815 : INFO : common : yaml file: config\config.yaml loaded successfully]
[2025-01-19 12:32:28,815 : INFO : common : yaml file: params.yaml loaded successfully]
[2025-01-19 12:32:28,815 : INFO : common : created directory at: artifacts]
[2025-01-19 12:32:28,815 : INFO : common : created directory at: artifacts/data_ingestion]
[2025-01-19 12:32:28,815 : INFO : data_ingestion1 : file already exists]
[2025-01-19 12:32:28,908 : INFO : main : DATA INGESTION STAGE has completed]
[2025-01-19 12:32:28,909 : INFO : main : <----------------------------------->]
[2025-01-19 12:32:28,909 : INFO : main : DATA TRANSFORMATION STAGE has initiated]
[2025-01-19 12:32:28,911 : INFO : common : yaml file: config\config.yaml loaded successfully]
[2025-01-19 12:32:28,911 : INFO : common : yaml file: params.yaml loaded successfully]
[2025-01-19 12:32:28,911 : INFO : common : created directory at: artifacts]
[2025-01-19 12:32:28,911 : INFO : common : created directory at: artifacts/data_transformation]
[2025-01-19 12:32:30,722 : INFO : main : DATA TRANSFORMATION STAGE has completed]
[2025-01-19 12:32:30,722 : INFO : main : <----------------------------------->]
[2025-01-19 12:32:30,723 : INFO : main : <----------------------------------->]
[2025-01-19 12:32:30,723 : INFO : main : MODEL TRAINING STAGE has initiated]
[2025-01-19 12:32:30,723 : INFO : common : yaml file: config\config.yaml loaded successfully]
[2025-01-19 12:32:30,723 : INFO : common : yaml file: params.yaml loaded successfully]
[2025-01-19 12:32:30,723 : INFO : common : created directory at: artifacts]
[2025-01-19 12:32:30,723 : INFO : common : created directory at: artifacts/model_evaluation]
[2025-01-19 12:32:34,744 : ERROR : main : name 'evaluate' is not defined]
Traceback (most recent call last):
  File "C:\Users\heman\Desktop\Text-Summarizer\main.py", line 26, in <module>
    initiate_model_evaluation=ModelEvaluationPipeline.evaluate_model()
                              ^^^^^^^^^^^^^^^^^^^^^^^^^^^^^^^^^^^^^^^^
  File "C:\Users\heman\Desktop\Text-Summarizer\src\Text_Summarizer\pipeline\stage_model_evaluation.py", line 13, in evaluate_model
    model_eval.evaluate()
  File "C:\Users\heman\Desktop\Text-Summarizer\src\Text_Summarizer\components\model_evaluation.py", line 68, in evaluate
    rouge_metric = evaluate.load('rouge')
                   ^^^^^^^^
NameError: name 'evaluate' is not defined
[2025-01-19 12:32:55,849 : INFO : config : PyTorch version 2.5.1 available.]
[2025-01-19 12:32:56,337 : INFO : main : DATA INGESTION STAGE has initiated]
[2025-01-19 12:32:56,337 : INFO : common : yaml file: config\config.yaml loaded successfully]
[2025-01-19 12:32:56,344 : INFO : common : yaml file: params.yaml loaded successfully]
[2025-01-19 12:32:56,344 : INFO : common : created directory at: artifacts]
[2025-01-19 12:32:56,344 : INFO : common : created directory at: artifacts/data_ingestion]
[2025-01-19 12:32:56,344 : INFO : data_ingestion1 : file already exists]
[2025-01-19 12:32:56,440 : INFO : main : DATA INGESTION STAGE has completed]
[2025-01-19 12:32:56,440 : INFO : main : <----------------------------------->]
[2025-01-19 12:32:56,440 : INFO : main : DATA TRANSFORMATION STAGE has initiated]
[2025-01-19 12:32:56,442 : INFO : common : yaml file: config\config.yaml loaded successfully]
[2025-01-19 12:32:56,442 : INFO : common : yaml file: params.yaml loaded successfully]
[2025-01-19 12:32:56,444 : INFO : common : created directory at: artifacts]
[2025-01-19 12:32:56,445 : INFO : common : created directory at: artifacts/data_transformation]
[2025-01-19 12:33:35,631 : INFO : main : DATA TRANSFORMATION STAGE has completed]
[2025-01-19 12:33:35,631 : INFO : main : <----------------------------------->]
[2025-01-19 12:33:35,631 : INFO : main : <----------------------------------->]
[2025-01-19 12:33:35,631 : INFO : main : MODEL TRAINING STAGE has initiated]
[2025-01-19 12:33:35,633 : INFO : common : yaml file: config\config.yaml loaded successfully]
[2025-01-19 12:33:35,635 : INFO : common : yaml file: params.yaml loaded successfully]
[2025-01-19 12:33:35,635 : INFO : common : created directory at: artifacts]
[2025-01-19 12:33:35,636 : INFO : common : created directory at: artifacts/model_evaluation]
[2025-01-19 12:33:40,999 : WARNING : loading : Using the latest cached version of the module from C:\Users\heman\.cache\huggingface\modules\evaluate_modules\metrics\evaluate-metric--rouge\b01e0accf3bd6dd24839b769a5fda24e14995071570870922c71970b3a6ed886 (last modified on Tue Jan 14 18:16:51 2025) since it couldn't be found locally at evaluate-metric--rouge, or remotely on the Hugging Face Hub.]
[2025-01-19 12:57:59,454 : INFO : server : Started server process [3440]]
[2025-01-19 12:57:59,454 : INFO : on : Waiting for application startup.]
[2025-01-19 12:57:59,454 : INFO : on : Application startup complete.]
[2025-01-19 12:57:59,461 : INFO : server : Uvicorn running on http://0.0.0.0:8080 (Press CTRL+C to quit)]
[2025-01-19 12:58:26,297 : INFO : server : Shutting down]
[2025-01-19 12:58:26,398 : INFO : on : Waiting for application shutdown.]
[2025-01-19 12:58:26,398 : INFO : on : Application shutdown complete.]
[2025-01-19 12:58:26,399 : INFO : server : Finished server process [3440]]
[2025-01-19 12:58:34,986 : INFO : server : Started server process [16100]]
[2025-01-19 12:58:34,986 : INFO : on : Waiting for application startup.]
[2025-01-19 12:58:34,988 : INFO : on : Application startup complete.]
[2025-01-19 12:58:34,989 : INFO : server : Uvicorn running on http://127.0.0.1:8080 (Press CTRL+C to quit)]
[2025-01-19 12:59:57,541 : ERROR : h11_impl : Exception in ASGI application
]
Traceback (most recent call last):
  File "C:\Users\heman\Desktop\Text-Summarizer\myvenv\Lib\site-packages\uvicorn\protocols\http\h11_impl.py", line 404, in run_asgi
    result = await app(  # type: ignore[func-returns-value]
             ^^^^^^^^^^^^^^^^^^^^^^^^^^^^^^^^^^^^^^^^^^^^^^
  File "C:\Users\heman\Desktop\Text-Summarizer\myvenv\Lib\site-packages\uvicorn\middleware\proxy_headers.py", line 78, in __call__
    return await self.app(scope, receive, send)
           ^^^^^^^^^^^^^^^^^^^^^^^^^^^^^^^^^^^^
  File "C:\Users\heman\Desktop\Text-Summarizer\myvenv\Lib\site-packages\fastapi\applications.py", line 269, in __call__
    await super().__call__(scope, receive, send)
  File "C:\Users\heman\Desktop\Text-Summarizer\myvenv\Lib\site-packages\starlette\applications.py", line 124, in __call__
    await self.middleware_stack(scope, receive, send)
  File "C:\Users\heman\Desktop\Text-Summarizer\myvenv\Lib\site-packages\starlette\middleware\errors.py", line 184, in __call__
    raise exc
  File "C:\Users\heman\Desktop\Text-Summarizer\myvenv\Lib\site-packages\starlette\middleware\errors.py", line 162, in __call__
    await self.app(scope, receive, _send)
  File "C:\Users\heman\Desktop\Text-Summarizer\myvenv\Lib\site-packages\starlette\exceptions.py", line 93, in __call__
    raise exc
  File "C:\Users\heman\Desktop\Text-Summarizer\myvenv\Lib\site-packages\starlette\exceptions.py", line 82, in __call__
    await self.app(scope, receive, sender)
  File "C:\Users\heman\Desktop\Text-Summarizer\myvenv\Lib\site-packages\fastapi\middleware\asyncexitstack.py", line 21, in __call__
    raise e
  File "C:\Users\heman\Desktop\Text-Summarizer\myvenv\Lib\site-packages\fastapi\middleware\asyncexitstack.py", line 18, in __call__
    await self.app(scope, receive, send)
  File "C:\Users\heman\Desktop\Text-Summarizer\myvenv\Lib\site-packages\starlette\routing.py", line 670, in __call__
    await route.handle(scope, receive, send)
  File "C:\Users\heman\Desktop\Text-Summarizer\myvenv\Lib\site-packages\starlette\routing.py", line 266, in handle
    await self.app(scope, receive, send)
  File "C:\Users\heman\Desktop\Text-Summarizer\myvenv\Lib\site-packages\starlette\routing.py", line 65, in app
    response = await func(request)
               ^^^^^^^^^^^^^^^^^^^
  File "C:\Users\heman\Desktop\Text-Summarizer\myvenv\Lib\site-packages\fastapi\routing.py", line 227, in app
    raw_response = await run_endpoint_function(
                   ^^^^^^^^^^^^^^^^^^^^^^^^^^^^
  File "C:\Users\heman\Desktop\Text-Summarizer\myvenv\Lib\site-packages\fastapi\routing.py", line 160, in run_endpoint_function
    return await dependant.call(**values)
           ^^^^^^^^^^^^^^^^^^^^^^^^^^^^^^
  File "C:\Users\heman\Desktop\Text-Summarizer\app.py", line 41, in predict_route
    raise e
  File "C:\Users\heman\Desktop\Text-Summarizer\app.py", line 37, in predict_route
    obj = PredictionPipeline()
          ^^^^^^^^^^^^^^^^^^^^
  File "C:\Users\heman\Desktop\Text-Summarizer\src\Text_Summarizer\pipeline\prediction_pipeline.py", line 8, in __init__
    self.config = ConfigurationManagerME.get_model_eval_config()
                  ^^^^^^^^^^^^^^^^^^^^^^^^^^^^^^^^^^^^^^^^^^^^^^
TypeError: ConfigurationManagerME.get_model_eval_config() missing 1 required positional argument: 'self'
[2025-01-19 13:03:28,411 : ERROR : h11_impl : Exception in ASGI application
]
Traceback (most recent call last):
  File "C:\Users\heman\Desktop\Text-Summarizer\myvenv\Lib\site-packages\uvicorn\protocols\http\h11_impl.py", line 404, in run_asgi
    result = await app(  # type: ignore[func-returns-value]
             ^^^^^^^^^^^^^^^^^^^^^^^^^^^^^^^^^^^^^^^^^^^^^^
  File "C:\Users\heman\Desktop\Text-Summarizer\myvenv\Lib\site-packages\uvicorn\middleware\proxy_headers.py", line 78, in __call__
    return await self.app(scope, receive, send)
           ^^^^^^^^^^^^^^^^^^^^^^^^^^^^^^^^^^^^
  File "C:\Users\heman\Desktop\Text-Summarizer\myvenv\Lib\site-packages\fastapi\applications.py", line 269, in __call__
    await super().__call__(scope, receive, send)
  File "C:\Users\heman\Desktop\Text-Summarizer\myvenv\Lib\site-packages\starlette\applications.py", line 124, in __call__
    await self.middleware_stack(scope, receive, send)
  File "C:\Users\heman\Desktop\Text-Summarizer\myvenv\Lib\site-packages\starlette\middleware\errors.py", line 184, in __call__
    raise exc
  File "C:\Users\heman\Desktop\Text-Summarizer\myvenv\Lib\site-packages\starlette\middleware\errors.py", line 162, in __call__
    await self.app(scope, receive, _send)
  File "C:\Users\heman\Desktop\Text-Summarizer\myvenv\Lib\site-packages\starlette\exceptions.py", line 93, in __call__
    raise exc
  File "C:\Users\heman\Desktop\Text-Summarizer\myvenv\Lib\site-packages\starlette\exceptions.py", line 82, in __call__
    await self.app(scope, receive, sender)
  File "C:\Users\heman\Desktop\Text-Summarizer\myvenv\Lib\site-packages\fastapi\middleware\asyncexitstack.py", line 21, in __call__
    raise e
  File "C:\Users\heman\Desktop\Text-Summarizer\myvenv\Lib\site-packages\fastapi\middleware\asyncexitstack.py", line 18, in __call__
    await self.app(scope, receive, send)
  File "C:\Users\heman\Desktop\Text-Summarizer\myvenv\Lib\site-packages\starlette\routing.py", line 670, in __call__
    await route.handle(scope, receive, send)
  File "C:\Users\heman\Desktop\Text-Summarizer\myvenv\Lib\site-packages\starlette\routing.py", line 266, in handle
    await self.app(scope, receive, send)
  File "C:\Users\heman\Desktop\Text-Summarizer\myvenv\Lib\site-packages\starlette\routing.py", line 65, in app
    response = await func(request)
               ^^^^^^^^^^^^^^^^^^^
  File "C:\Users\heman\Desktop\Text-Summarizer\myvenv\Lib\site-packages\fastapi\routing.py", line 227, in app
    raw_response = await run_endpoint_function(
                   ^^^^^^^^^^^^^^^^^^^^^^^^^^^^
  File "C:\Users\heman\Desktop\Text-Summarizer\myvenv\Lib\site-packages\fastapi\routing.py", line 160, in run_endpoint_function
    return await dependant.call(**values)
           ^^^^^^^^^^^^^^^^^^^^^^^^^^^^^^
  File "C:\Users\heman\Desktop\Text-Summarizer\app.py", line 41, in predict_route
    raise e
  File "C:\Users\heman\Desktop\Text-Summarizer\app.py", line 37, in predict_route
    obj = PredictionPipeline()
          ^^^^^^^^^^^^^^^^^^^^
  File "C:\Users\heman\Desktop\Text-Summarizer\src\Text_Summarizer\pipeline\prediction_pipeline.py", line 8, in __init__
    config_manager = ConfigurationManagerME()  # Create an instance
                  ^^^^^^^^^^^^^^^^^^^^^^^^^^^^^^^^^^^^^^^^^^^^^^
TypeError: ConfigurationManagerME.get_model_eval_config() missing 1 required positional argument: 'self'
[2025-01-19 13:03:33,997 : ERROR : h11_impl : Exception in ASGI application
]
Traceback (most recent call last):
  File "C:\Users\heman\Desktop\Text-Summarizer\myvenv\Lib\site-packages\uvicorn\protocols\http\h11_impl.py", line 404, in run_asgi
    result = await app(  # type: ignore[func-returns-value]
             ^^^^^^^^^^^^^^^^^^^^^^^^^^^^^^^^^^^^^^^^^^^^^^
  File "C:\Users\heman\Desktop\Text-Summarizer\myvenv\Lib\site-packages\uvicorn\middleware\proxy_headers.py", line 78, in __call__
    return await self.app(scope, receive, send)
           ^^^^^^^^^^^^^^^^^^^^^^^^^^^^^^^^^^^^
  File "C:\Users\heman\Desktop\Text-Summarizer\myvenv\Lib\site-packages\fastapi\applications.py", line 269, in __call__
    await super().__call__(scope, receive, send)
  File "C:\Users\heman\Desktop\Text-Summarizer\myvenv\Lib\site-packages\starlette\applications.py", line 124, in __call__
    await self.middleware_stack(scope, receive, send)
  File "C:\Users\heman\Desktop\Text-Summarizer\myvenv\Lib\site-packages\starlette\middleware\errors.py", line 184, in __call__
    raise exc
  File "C:\Users\heman\Desktop\Text-Summarizer\myvenv\Lib\site-packages\starlette\middleware\errors.py", line 162, in __call__
    await self.app(scope, receive, _send)
  File "C:\Users\heman\Desktop\Text-Summarizer\myvenv\Lib\site-packages\starlette\exceptions.py", line 93, in __call__
    raise exc
  File "C:\Users\heman\Desktop\Text-Summarizer\myvenv\Lib\site-packages\starlette\exceptions.py", line 82, in __call__
    await self.app(scope, receive, sender)
  File "C:\Users\heman\Desktop\Text-Summarizer\myvenv\Lib\site-packages\fastapi\middleware\asyncexitstack.py", line 21, in __call__
    raise e
  File "C:\Users\heman\Desktop\Text-Summarizer\myvenv\Lib\site-packages\fastapi\middleware\asyncexitstack.py", line 18, in __call__
    await self.app(scope, receive, send)
  File "C:\Users\heman\Desktop\Text-Summarizer\myvenv\Lib\site-packages\starlette\routing.py", line 670, in __call__
    await route.handle(scope, receive, send)
  File "C:\Users\heman\Desktop\Text-Summarizer\myvenv\Lib\site-packages\starlette\routing.py", line 266, in handle
    await self.app(scope, receive, send)
  File "C:\Users\heman\Desktop\Text-Summarizer\myvenv\Lib\site-packages\starlette\routing.py", line 65, in app
    response = await func(request)
               ^^^^^^^^^^^^^^^^^^^
  File "C:\Users\heman\Desktop\Text-Summarizer\myvenv\Lib\site-packages\fastapi\routing.py", line 227, in app
    raw_response = await run_endpoint_function(
                   ^^^^^^^^^^^^^^^^^^^^^^^^^^^^
  File "C:\Users\heman\Desktop\Text-Summarizer\myvenv\Lib\site-packages\fastapi\routing.py", line 160, in run_endpoint_function
    return await dependant.call(**values)
           ^^^^^^^^^^^^^^^^^^^^^^^^^^^^^^
  File "C:\Users\heman\Desktop\Text-Summarizer\app.py", line 41, in predict_route
    raise e
  File "C:\Users\heman\Desktop\Text-Summarizer\app.py", line 37, in predict_route
    obj = PredictionPipeline()
          ^^^^^^^^^^^^^^^^^^^^
  File "C:\Users\heman\Desktop\Text-Summarizer\src\Text_Summarizer\pipeline\prediction_pipeline.py", line 8, in __init__
    config_manager = ConfigurationManagerME()  # Create an instance
                  ^^^^^^^^^^^^^^^^^^^^^^^^^^^^^^^^^^^^^^^^^^^^^^
TypeError: ConfigurationManagerME.get_model_eval_config() missing 1 required positional argument: 'self'
[2025-01-19 13:04:03,473 : ERROR : h11_impl : Exception in ASGI application
]
Traceback (most recent call last):
  File "C:\Users\heman\Desktop\Text-Summarizer\myvenv\Lib\site-packages\uvicorn\protocols\http\h11_impl.py", line 404, in run_asgi
    result = await app(  # type: ignore[func-returns-value]
             ^^^^^^^^^^^^^^^^^^^^^^^^^^^^^^^^^^^^^^^^^^^^^^
  File "C:\Users\heman\Desktop\Text-Summarizer\myvenv\Lib\site-packages\uvicorn\middleware\proxy_headers.py", line 78, in __call__
    return await self.app(scope, receive, send)
           ^^^^^^^^^^^^^^^^^^^^^^^^^^^^^^^^^^^^
  File "C:\Users\heman\Desktop\Text-Summarizer\myvenv\Lib\site-packages\fastapi\applications.py", line 269, in __call__
    await super().__call__(scope, receive, send)
  File "C:\Users\heman\Desktop\Text-Summarizer\myvenv\Lib\site-packages\starlette\applications.py", line 124, in __call__
    await self.middleware_stack(scope, receive, send)
  File "C:\Users\heman\Desktop\Text-Summarizer\myvenv\Lib\site-packages\starlette\middleware\errors.py", line 184, in __call__
    raise exc
  File "C:\Users\heman\Desktop\Text-Summarizer\myvenv\Lib\site-packages\starlette\middleware\errors.py", line 162, in __call__
    await self.app(scope, receive, _send)
  File "C:\Users\heman\Desktop\Text-Summarizer\myvenv\Lib\site-packages\starlette\exceptions.py", line 93, in __call__
    raise exc
  File "C:\Users\heman\Desktop\Text-Summarizer\myvenv\Lib\site-packages\starlette\exceptions.py", line 82, in __call__
    await self.app(scope, receive, sender)
  File "C:\Users\heman\Desktop\Text-Summarizer\myvenv\Lib\site-packages\fastapi\middleware\asyncexitstack.py", line 21, in __call__
    raise e
  File "C:\Users\heman\Desktop\Text-Summarizer\myvenv\Lib\site-packages\fastapi\middleware\asyncexitstack.py", line 18, in __call__
    await self.app(scope, receive, send)
  File "C:\Users\heman\Desktop\Text-Summarizer\myvenv\Lib\site-packages\starlette\routing.py", line 670, in __call__
    await route.handle(scope, receive, send)
  File "C:\Users\heman\Desktop\Text-Summarizer\myvenv\Lib\site-packages\starlette\routing.py", line 266, in handle
    await self.app(scope, receive, send)
  File "C:\Users\heman\Desktop\Text-Summarizer\myvenv\Lib\site-packages\starlette\routing.py", line 65, in app
    response = await func(request)
               ^^^^^^^^^^^^^^^^^^^
  File "C:\Users\heman\Desktop\Text-Summarizer\myvenv\Lib\site-packages\fastapi\routing.py", line 227, in app
    raw_response = await run_endpoint_function(
                   ^^^^^^^^^^^^^^^^^^^^^^^^^^^^
  File "C:\Users\heman\Desktop\Text-Summarizer\myvenv\Lib\site-packages\fastapi\routing.py", line 160, in run_endpoint_function
    return await dependant.call(**values)
           ^^^^^^^^^^^^^^^^^^^^^^^^^^^^^^
  File "C:\Users\heman\Desktop\Text-Summarizer\app.py", line 41, in predict_route
    raise e
  File "C:\Users\heman\Desktop\Text-Summarizer\app.py", line 37, in predict_route
    obj = PredictionPipeline()
          ^^^^^^^^^^^^^^^^^^^^
  File "C:\Users\heman\Desktop\Text-Summarizer\src\Text_Summarizer\pipeline\prediction_pipeline.py", line 8, in __init__
    pass
         
TypeError: ConfigurationManagerME.get_model_eval_config() missing 1 required positional argument: 'self'
[2025-01-19 13:04:24,540 : ERROR : h11_impl : Exception in ASGI application
]
Traceback (most recent call last):
  File "C:\Users\heman\Desktop\Text-Summarizer\myvenv\Lib\site-packages\uvicorn\protocols\http\h11_impl.py", line 404, in run_asgi
    result = await app(  # type: ignore[func-returns-value]
             ^^^^^^^^^^^^^^^^^^^^^^^^^^^^^^^^^^^^^^^^^^^^^^
  File "C:\Users\heman\Desktop\Text-Summarizer\myvenv\Lib\site-packages\uvicorn\middleware\proxy_headers.py", line 78, in __call__
    return await self.app(scope, receive, send)
           ^^^^^^^^^^^^^^^^^^^^^^^^^^^^^^^^^^^^
  File "C:\Users\heman\Desktop\Text-Summarizer\myvenv\Lib\site-packages\fastapi\applications.py", line 269, in __call__
    await super().__call__(scope, receive, send)
  File "C:\Users\heman\Desktop\Text-Summarizer\myvenv\Lib\site-packages\starlette\applications.py", line 124, in __call__
    await self.middleware_stack(scope, receive, send)
  File "C:\Users\heman\Desktop\Text-Summarizer\myvenv\Lib\site-packages\starlette\middleware\errors.py", line 184, in __call__
    raise exc
  File "C:\Users\heman\Desktop\Text-Summarizer\myvenv\Lib\site-packages\starlette\middleware\errors.py", line 162, in __call__
    await self.app(scope, receive, _send)
  File "C:\Users\heman\Desktop\Text-Summarizer\myvenv\Lib\site-packages\starlette\exceptions.py", line 93, in __call__
    raise exc
  File "C:\Users\heman\Desktop\Text-Summarizer\myvenv\Lib\site-packages\starlette\exceptions.py", line 82, in __call__
    await self.app(scope, receive, sender)
  File "C:\Users\heman\Desktop\Text-Summarizer\myvenv\Lib\site-packages\fastapi\middleware\asyncexitstack.py", line 21, in __call__
    raise e
  File "C:\Users\heman\Desktop\Text-Summarizer\myvenv\Lib\site-packages\fastapi\middleware\asyncexitstack.py", line 18, in __call__
    await self.app(scope, receive, send)
  File "C:\Users\heman\Desktop\Text-Summarizer\myvenv\Lib\site-packages\starlette\routing.py", line 670, in __call__
    await route.handle(scope, receive, send)
  File "C:\Users\heman\Desktop\Text-Summarizer\myvenv\Lib\site-packages\starlette\routing.py", line 266, in handle
    await self.app(scope, receive, send)
  File "C:\Users\heman\Desktop\Text-Summarizer\myvenv\Lib\site-packages\starlette\routing.py", line 65, in app
    response = await func(request)
               ^^^^^^^^^^^^^^^^^^^
  File "C:\Users\heman\Desktop\Text-Summarizer\myvenv\Lib\site-packages\fastapi\routing.py", line 227, in app
    raw_response = await run_endpoint_function(
                   ^^^^^^^^^^^^^^^^^^^^^^^^^^^^
  File "C:\Users\heman\Desktop\Text-Summarizer\myvenv\Lib\site-packages\fastapi\routing.py", line 160, in run_endpoint_function
    return await dependant.call(**values)
           ^^^^^^^^^^^^^^^^^^^^^^^^^^^^^^
  File "C:\Users\heman\Desktop\Text-Summarizer\app.py", line 41, in predict_route
    raise e
  File "C:\Users\heman\Desktop\Text-Summarizer\app.py", line 37, in predict_route
    obj = PredictionPipeline()
          ^^^^^^^^^^^^^^^^^^^^
  File "C:\Users\heman\Desktop\Text-Summarizer\src\Text_Summarizer\pipeline\prediction_pipeline.py", line 8, in __init__
    pass
         
TypeError: ConfigurationManagerME.get_model_eval_config() missing 1 required positional argument: 'self'
[2025-01-19 13:20:38,077 : INFO : server : Shutting down]
[2025-01-19 13:20:38,185 : INFO : on : Waiting for application shutdown.]
[2025-01-19 13:20:38,187 : INFO : on : Application shutdown complete.]
[2025-01-19 13:20:38,187 : INFO : server : Finished server process [16100]]
[2025-01-19 13:20:46,789 : INFO : server : Started server process [3208]]
[2025-01-19 13:20:46,789 : INFO : on : Waiting for application startup.]
[2025-01-19 13:20:46,789 : INFO : on : Application startup complete.]
[2025-01-19 13:20:46,797 : INFO : server : Uvicorn running on http://127.0.0.1:8080 (Press CTRL+C to quit)]
[2025-01-19 13:20:58,048 : INFO : common : yaml file: config\config.yaml loaded successfully]
[2025-01-19 13:20:58,048 : INFO : common : yaml file: params.yaml loaded successfully]
[2025-01-19 13:20:58,050 : INFO : common : created directory at: artifacts]
[2025-01-19 13:20:58,050 : INFO : common : created directory at: artifacts/model_evaluation]
[2025-01-19 13:20:58,051 : ERROR : h11_impl : Exception in ASGI application
]
Traceback (most recent call last):
  File "C:\Users\heman\Desktop\Text-Summarizer\myvenv\Lib\site-packages\uvicorn\protocols\http\h11_impl.py", line 404, in run_asgi
    result = await app(  # type: ignore[func-returns-value]
             ^^^^^^^^^^^^^^^^^^^^^^^^^^^^^^^^^^^^^^^^^^^^^^
  File "C:\Users\heman\Desktop\Text-Summarizer\myvenv\Lib\site-packages\uvicorn\middleware\proxy_headers.py", line 78, in __call__
    return await self.app(scope, receive, send)
           ^^^^^^^^^^^^^^^^^^^^^^^^^^^^^^^^^^^^
  File "C:\Users\heman\Desktop\Text-Summarizer\myvenv\Lib\site-packages\fastapi\applications.py", line 269, in __call__
    await super().__call__(scope, receive, send)
  File "C:\Users\heman\Desktop\Text-Summarizer\myvenv\Lib\site-packages\starlette\applications.py", line 124, in __call__
    await self.middleware_stack(scope, receive, send)
  File "C:\Users\heman\Desktop\Text-Summarizer\myvenv\Lib\site-packages\starlette\middleware\errors.py", line 184, in __call__
    raise exc
  File "C:\Users\heman\Desktop\Text-Summarizer\myvenv\Lib\site-packages\starlette\middleware\errors.py", line 162, in __call__
    await self.app(scope, receive, _send)
  File "C:\Users\heman\Desktop\Text-Summarizer\myvenv\Lib\site-packages\starlette\exceptions.py", line 93, in __call__
    raise exc
  File "C:\Users\heman\Desktop\Text-Summarizer\myvenv\Lib\site-packages\starlette\exceptions.py", line 82, in __call__
    await self.app(scope, receive, sender)
  File "C:\Users\heman\Desktop\Text-Summarizer\myvenv\Lib\site-packages\fastapi\middleware\asyncexitstack.py", line 21, in __call__
    raise e
  File "C:\Users\heman\Desktop\Text-Summarizer\myvenv\Lib\site-packages\fastapi\middleware\asyncexitstack.py", line 18, in __call__
    await self.app(scope, receive, send)
  File "C:\Users\heman\Desktop\Text-Summarizer\myvenv\Lib\site-packages\starlette\routing.py", line 670, in __call__
    await route.handle(scope, receive, send)
  File "C:\Users\heman\Desktop\Text-Summarizer\myvenv\Lib\site-packages\starlette\routing.py", line 266, in handle
    await self.app(scope, receive, send)
  File "C:\Users\heman\Desktop\Text-Summarizer\myvenv\Lib\site-packages\starlette\routing.py", line 65, in app
    response = await func(request)
               ^^^^^^^^^^^^^^^^^^^
  File "C:\Users\heman\Desktop\Text-Summarizer\myvenv\Lib\site-packages\fastapi\routing.py", line 227, in app
    raw_response = await run_endpoint_function(
                   ^^^^^^^^^^^^^^^^^^^^^^^^^^^^
  File "C:\Users\heman\Desktop\Text-Summarizer\myvenv\Lib\site-packages\fastapi\routing.py", line 160, in run_endpoint_function
    return await dependant.call(**values)
           ^^^^^^^^^^^^^^^^^^^^^^^^^^^^^^
  File "C:\Users\heman\Desktop\Text-Summarizer\app.py", line 41, in predict_route
    raise e
  File "C:\Users\heman\Desktop\Text-Summarizer\app.py", line 38, in predict_route
    text = obj.predict(text)
           ^^^^^^^^^^^^^^^^^
  File "C:\Users\heman\Desktop\Text-Summarizer\src\Text_Summarizer\pipeline\prediction_pipeline.py", line 13, in predict
    tokenizer = AutoTokenizer.from_pretrained(self.config.tokenizer_name)
                                              ^^^^^^^^^^^^^^^^^^^^^^^^^^
AttributeError: 'ModelEvaluationConfig' object has no attribute 'tokenizer_name'
[2025-01-19 13:21:22,808 : INFO : server : Shutting down]
[2025-01-19 13:21:22,916 : INFO : on : Waiting for application shutdown.]
[2025-01-19 13:21:22,917 : INFO : on : Application shutdown complete.]
[2025-01-19 13:21:22,917 : INFO : server : Finished server process [3208]]
[2025-01-19 13:21:31,116 : INFO : server : Started server process [21424]]
[2025-01-19 13:21:31,116 : INFO : on : Waiting for application startup.]
[2025-01-19 13:21:31,116 : INFO : on : Application startup complete.]
[2025-01-19 13:21:31,116 : INFO : server : Uvicorn running on http://127.0.0.1:8080 (Press CTRL+C to quit)]
[2025-01-19 13:21:54,694 : INFO : common : yaml file: config\config.yaml loaded successfully]
[2025-01-19 13:21:54,694 : INFO : common : yaml file: params.yaml loaded successfully]
[2025-01-19 13:21:54,696 : INFO : common : created directory at: artifacts]
[2025-01-19 13:21:54,696 : INFO : common : created directory at: artifacts/model_evaluation]
[2025-01-19 13:21:55,186 : ERROR : h11_impl : Exception in ASGI application
]
Traceback (most recent call last):
  File "C:\Users\heman\Desktop\Text-Summarizer\myvenv\Lib\site-packages\uvicorn\protocols\http\h11_impl.py", line 404, in run_asgi
    result = await app(  # type: ignore[func-returns-value]
             ^^^^^^^^^^^^^^^^^^^^^^^^^^^^^^^^^^^^^^^^^^^^^^
  File "C:\Users\heman\Desktop\Text-Summarizer\myvenv\Lib\site-packages\uvicorn\middleware\proxy_headers.py", line 78, in __call__
    return await self.app(scope, receive, send)
           ^^^^^^^^^^^^^^^^^^^^^^^^^^^^^^^^^^^^
  File "C:\Users\heman\Desktop\Text-Summarizer\myvenv\Lib\site-packages\fastapi\applications.py", line 269, in __call__
    await super().__call__(scope, receive, send)
  File "C:\Users\heman\Desktop\Text-Summarizer\myvenv\Lib\site-packages\starlette\applications.py", line 124, in __call__
    await self.middleware_stack(scope, receive, send)
  File "C:\Users\heman\Desktop\Text-Summarizer\myvenv\Lib\site-packages\starlette\middleware\errors.py", line 184, in __call__
    raise exc
  File "C:\Users\heman\Desktop\Text-Summarizer\myvenv\Lib\site-packages\starlette\middleware\errors.py", line 162, in __call__
    await self.app(scope, receive, _send)
  File "C:\Users\heman\Desktop\Text-Summarizer\myvenv\Lib\site-packages\starlette\exceptions.py", line 93, in __call__
    raise exc
  File "C:\Users\heman\Desktop\Text-Summarizer\myvenv\Lib\site-packages\starlette\exceptions.py", line 82, in __call__
    await self.app(scope, receive, sender)
  File "C:\Users\heman\Desktop\Text-Summarizer\myvenv\Lib\site-packages\fastapi\middleware\asyncexitstack.py", line 21, in __call__
    raise e
  File "C:\Users\heman\Desktop\Text-Summarizer\myvenv\Lib\site-packages\fastapi\middleware\asyncexitstack.py", line 18, in __call__
    await self.app(scope, receive, send)
  File "C:\Users\heman\Desktop\Text-Summarizer\myvenv\Lib\site-packages\starlette\routing.py", line 670, in __call__
    await route.handle(scope, receive, send)
  File "C:\Users\heman\Desktop\Text-Summarizer\myvenv\Lib\site-packages\starlette\routing.py", line 266, in handle
    await self.app(scope, receive, send)
  File "C:\Users\heman\Desktop\Text-Summarizer\myvenv\Lib\site-packages\starlette\routing.py", line 65, in app
    response = await func(request)
               ^^^^^^^^^^^^^^^^^^^
  File "C:\Users\heman\Desktop\Text-Summarizer\myvenv\Lib\site-packages\fastapi\routing.py", line 227, in app
    raw_response = await run_endpoint_function(
                   ^^^^^^^^^^^^^^^^^^^^^^^^^^^^
  File "C:\Users\heman\Desktop\Text-Summarizer\myvenv\Lib\site-packages\fastapi\routing.py", line 160, in run_endpoint_function
    return await dependant.call(**values)
           ^^^^^^^^^^^^^^^^^^^^^^^^^^^^^^
  File "C:\Users\heman\Desktop\Text-Summarizer\app.py", line 41, in predict_route
    raise e
  File "C:\Users\heman\Desktop\Text-Summarizer\app.py", line 38, in predict_route
    text = obj.predict(text)
           ^^^^^^^^^^^^^^^^^
  File "C:\Users\heman\Desktop\Text-Summarizer\src\Text_Summarizer\pipeline\prediction_pipeline.py", line 14, in predict
    model_name = AutoTokenizer.from_pretrained(self.config.model_path)
                 ^^^^^^^^^^^^^^^^^^^^^^^^^^^^^^^^^^^^^^^^^^^^^^^^^^^^^
  File "C:\Users\heman\Desktop\Text-Summarizer\myvenv\Lib\site-packages\transformers\models\auto\tokenization_auto.py", line 953, in from_pretrained
    return tokenizer_class_fast.from_pretrained(pretrained_model_name_or_path, *inputs, **kwargs)
           ^^^^^^^^^^^^^^^^^^^^^^^^^^^^^^^^^^^^^^^^^^^^^^^^^^^^^^^^^^^^^^^^^^^^^^^^^^^^^^^^^^^^^^
  File "C:\Users\heman\Desktop\Text-Summarizer\myvenv\Lib\site-packages\transformers\tokenization_utils_base.py", line 2020, in from_pretrained
    raise EnvironmentError(
OSError: Can't load tokenizer for 'artifacts/model_trainer/pegasus-samsum-trained'. If you were trying to load it from 'https://huggingface.co/models', make sure you don't have a local directory with the same name. Otherwise, make sure 'artifacts/model_trainer/pegasus-samsum-trained' is the correct path to a directory containing all relevant files for a PegasusTokenizerFast tokenizer.
[2025-01-19 13:23:58,648 : INFO : server : Shutting down]
[2025-01-19 13:23:58,755 : INFO : on : Waiting for application shutdown.]
[2025-01-19 13:23:58,756 : INFO : on : Application shutdown complete.]
[2025-01-19 13:23:58,756 : INFO : server : Finished server process [21424]]
[2025-01-19 13:24:07,085 : INFO : server : Started server process [2956]]
[2025-01-19 13:24:07,085 : INFO : on : Waiting for application startup.]
[2025-01-19 13:24:07,085 : INFO : on : Application startup complete.]
[2025-01-19 13:24:07,085 : INFO : server : Uvicorn running on http://127.0.0.1:8080 (Press CTRL+C to quit)]
[2025-01-19 13:24:20,441 : INFO : common : yaml file: config\config.yaml loaded successfully]
[2025-01-19 13:24:20,443 : INFO : common : yaml file: params.yaml loaded successfully]
[2025-01-19 13:24:20,443 : INFO : common : created directory at: artifacts]
[2025-01-19 13:24:20,444 : INFO : common : created directory at: artifacts/model_evaluation]
[2025-01-19 13:32:39,555 : INFO : server : Shutting down]
[2025-01-19 13:32:39,662 : INFO : on : Waiting for application shutdown.]
[2025-01-19 13:32:39,663 : INFO : on : Application shutdown complete.]
[2025-01-19 13:32:39,663 : INFO : server : Finished server process [2956]]
[2025-01-19 13:35:05,689 : INFO : server : Started server process [10812]]
[2025-01-19 13:35:05,689 : INFO : on : Waiting for application startup.]
[2025-01-19 13:35:05,689 : INFO : on : Application startup complete.]
[2025-01-19 13:35:05,689 : INFO : server : Uvicorn running on http://127.0.0.1:8080 (Press CTRL+C to quit)]
[2025-01-19 13:38:49,973 : INFO : server : Shutting down]
[2025-01-19 13:38:50,077 : INFO : on : Waiting for application shutdown.]
[2025-01-19 13:38:50,077 : INFO : on : Application shutdown complete.]
[2025-01-19 13:38:50,079 : INFO : server : Finished server process [10812]]
[2025-01-19 13:38:56,634 : INFO : server : Started server process [21016]]
[2025-01-19 13:38:56,635 : INFO : on : Waiting for application startup.]
[2025-01-19 13:38:56,635 : INFO : on : Application startup complete.]
[2025-01-19 13:38:56,636 : INFO : server : Uvicorn running on http://127.0.0.1:8080 (Press CTRL+C to quit)]
[2025-01-19 13:42:28,896 : INFO : server : Shutting down]
[2025-01-19 13:42:29,011 : INFO : on : Waiting for application shutdown.]
[2025-01-19 13:42:29,012 : INFO : on : Application shutdown complete.]
[2025-01-19 13:42:29,012 : INFO : server : Finished server process [21016]]
[2025-01-19 13:42:35,936 : INFO : server : Started server process [17756]]
[2025-01-19 13:42:35,938 : INFO : on : Waiting for application startup.]
[2025-01-19 13:42:35,938 : INFO : on : Application startup complete.]
[2025-01-19 13:42:35,939 : INFO : server : Uvicorn running on http://127.0.0.1:8080 (Press CTRL+C to quit)]
[2025-01-19 13:42:41,844 : INFO : server : Shutting down]
[2025-01-19 13:42:41,951 : INFO : on : Waiting for application shutdown.]
[2025-01-19 13:42:41,951 : INFO : on : Application shutdown complete.]
[2025-01-19 13:42:41,953 : INFO : server : Finished server process [17756]]
[2025-01-19 13:43:06,029 : INFO : server : Started server process [20976]]
[2025-01-19 13:43:06,031 : INFO : on : Waiting for application startup.]
[2025-01-19 13:43:06,031 : INFO : on : Application startup complete.]
[2025-01-19 13:43:06,031 : INFO : server : Uvicorn running on http://127.0.0.1:8080 (Press CTRL+C to quit)]
[2025-01-19 13:45:32,960 : INFO : server : Started server process [9804]]
[2025-01-19 13:45:32,960 : INFO : on : Waiting for application startup.]
[2025-01-19 13:45:32,960 : INFO : on : Application startup complete.]
[2025-01-19 13:45:32,960 : INFO : server : Uvicorn running on http://127.0.0.1:8080 (Press CTRL+C to quit)]
[2025-01-19 13:46:00,939 : INFO : common : yaml file: config\config.yaml loaded successfully]
[2025-01-19 13:46:00,940 : INFO : common : yaml file: params.yaml loaded successfully]
[2025-01-19 13:46:00,940 : INFO : common : created directory at: artifacts]
[2025-01-19 13:46:00,940 : INFO : common : created directory at: artifacts/model_evaluation]
[2025-01-19 13:47:59,688 : INFO : server : Shutting down]
[2025-01-19 13:47:59,796 : INFO : on : Waiting for application shutdown.]
[2025-01-19 13:47:59,797 : INFO : on : Application shutdown complete.]
[2025-01-19 13:47:59,797 : INFO : server : Finished server process [9804]]
[2025-01-19 13:48:05,323 : INFO : server : Started server process [20324]]
[2025-01-19 13:48:05,324 : INFO : on : Waiting for application startup.]
[2025-01-19 13:48:05,324 : INFO : on : Application startup complete.]
[2025-01-19 13:48:05,325 : INFO : server : Uvicorn running on http://127.0.0.1:8080 (Press CTRL+C to quit)]
[2025-01-19 13:48:17,446 : INFO : common : yaml file: config\config.yaml loaded successfully]
[2025-01-19 13:48:17,448 : INFO : common : yaml file: params.yaml loaded successfully]
[2025-01-19 13:48:17,449 : INFO : common : created directory at: artifacts]
[2025-01-19 13:48:17,449 : INFO : common : created directory at: artifacts/model_evaluation]
[2025-01-19 13:49:32,319 : INFO : common : yaml file: config\config.yaml loaded successfully]
[2025-01-19 13:49:32,320 : INFO : common : yaml file: params.yaml loaded successfully]
[2025-01-19 13:49:32,320 : INFO : common : created directory at: artifacts]
[2025-01-19 13:49:32,321 : INFO : common : created directory at: artifacts/model_evaluation]
[2025-01-19 13:50:47,165 : INFO : common : yaml file: config\config.yaml loaded successfully]
[2025-01-19 13:50:47,165 : INFO : common : yaml file: params.yaml loaded successfully]
[2025-01-19 13:50:47,165 : INFO : common : created directory at: artifacts]
[2025-01-19 13:50:47,165 : INFO : common : created directory at: artifacts/model_evaluation]
[2025-01-19 13:51:35,831 : INFO : config : PyTorch version 2.5.1 available.]
[2025-01-19 13:51:36,322 : INFO : main : DATA INGESTION STAGE has initiated]
[2025-01-19 13:51:36,324 : INFO : common : yaml file: config\config.yaml loaded successfully]
[2025-01-19 13:51:36,324 : INFO : common : yaml file: params.yaml loaded successfully]
[2025-01-19 13:51:36,326 : INFO : common : created directory at: artifacts]
[2025-01-19 13:51:36,326 : INFO : common : created directory at: artifacts/data_ingestion]
[2025-01-19 13:51:36,326 : INFO : data_ingestion1 : file already exists]
[2025-01-19 13:51:36,450 : INFO : main : DATA INGESTION STAGE has completed]
[2025-01-19 13:51:36,450 : INFO : main : <----------------------------------->]
[2025-01-19 13:51:36,450 : INFO : main : DATA TRANSFORMATION STAGE has initiated]
[2025-01-19 13:51:36,450 : INFO : common : yaml file: config\config.yaml loaded successfully]
[2025-01-19 13:51:36,450 : INFO : common : yaml file: params.yaml loaded successfully]
[2025-01-19 13:51:36,450 : INFO : common : created directory at: artifacts]
[2025-01-19 13:51:36,450 : INFO : common : created directory at: artifacts/data_transformation]
[2025-01-19 13:51:37,905 : INFO : main : DATA TRANSFORMATION STAGE has completed]
[2025-01-19 13:51:37,905 : INFO : main : <----------------------------------->]
[2025-01-19 13:51:37,905 : INFO : main : <----------------------------------->]
[2025-01-19 13:51:37,905 : INFO : main : MODEL TRAINING STAGE has initiated]
[2025-01-19 13:51:37,910 : INFO : common : yaml file: config\config.yaml loaded successfully]
[2025-01-19 13:51:37,910 : INFO : common : yaml file: params.yaml loaded successfully]
[2025-01-19 13:51:37,910 : INFO : common : created directory at: artifacts]
[2025-01-19 13:51:37,913 : INFO : common : created directory at: artifacts/model_evaluation]
[2025-01-19 13:51:48,126 : INFO : server : Shutting down]
[2025-01-19 13:51:48,241 : INFO : on : Waiting for application shutdown.]
[2025-01-19 13:51:48,241 : INFO : on : Application shutdown complete.]
[2025-01-19 13:51:48,241 : INFO : server : Finished server process [20324]]
